<?xml version="1.0"?>
<!-- Revolute-Revolute Manipulator -->
<robot name="open_manipulator_p" xmlns:xacro="http://www.ros.org/wiki/xacro">

  <!-- Import all Gazebo-customization elements, including Gazebo colors -->
  <xacro:include filename="$(find open_manipulator_p_description)/urdf/open_manipulator_p.gazebo.xacro"/>

  <!-- Import Rviz colors -->
  <xacro:include filename="$(find open_manipulator_p_description)/urdf/materials.xacro"/>

  <!-- Transmission macro -->
  <xacro:macro name="SimpleTransmission" params="joint n">
    <transmission name="tran${n}">
      <type>transmission_interface/SimpleTransmission</type>
      <joint name="${joint}">
        <hardwareInterface>hardware_interface/PositionJointInterface</hardwareInterface>
      </joint>
      <actuator name="motor${n}">
        <hardwareInterface>hardware_interface/PositionJointInterface</hardwareInterface>
        <mechanicalReduction>1</mechanicalReduction>
      </actuator>
    </transmission>
  </xacro:macro>

  <xacro:macro name="open_manipulator_p_macro" params="name parent *origin">
      
    <xacro:open_manipulator_p_gazebo_macro name="${name}"/>

    <joint name="${name}_fixed_joint" type="fixed">
      <xacro:insert_block name="origin"/>
      <parent link="${parent}"/>
      <child link="${name}_mount_link"/>
    </joint>

    <link name="${name}_mount_link"></link>

    <joint name="${name}_joint0" type="fixed">
      <parent link="${name}_mount_link"/>
      <child link="${name}_link1"/>
    </joint>

    <!-- link 1 -->
    <link name="${name}_link1">
      <collision>
        <origin xyz="0 0 0.063" rpy="0 0 0" />
        <geometry>
          <box size="0.054 0.054 0.126" />
        </geometry>
      </collision>

      <visual>
        <origin xyz="0 0 0" rpy="0 0 0"/>
        <geometry>
          <mesh filename="package://open_manipulator_p_description/meshes/link_1.stl" scale="0.001 0.001 0.001"/>
        </geometry>
        <material name="grey"/>
      </visual>

      <inertial>
        <origin xyz="0.00023 0.00000 0.06223" rpy="0 0 0"/>
        <mass value="0.85644"/>
        <inertia ixx="1.0" ixy="0.0" ixz="0.0" iyy="1.0" iyz="0.0" izz="1.0"/>
        <!--<inertia ixx="0.00121064" ixy="0.0" ixz="0.00001100" iyy="0.00120886" iyz="0.0" izz="0.00038103" />-->
      </inertial>
    </link>

    <!-- Joint 1 -->
    <joint name="${name}_joint1" type="revolute">
      <parent link="${name}_link1"/>
      <child link="${name}_link2"/>
      <origin xyz="0.0 0.0 0.126" rpy="0 0 0"/>
      <axis xyz="0 0 1"/>
      <limit velocity="6.5" effort="1000" lower="${-pi*0.5}" upper="${pi*0.5}"/>
      <dynamics damping="0.7"/>
    </joint>

    <!-- Transmission 1 -->
    <xacro:SimpleTransmission n="1" joint="${name}_joint1"/>

    <!-- link 2 -->
    <link name="${name}_link2">
      <collision>
        <origin xyz="0 0 0.03" rpy="0 0 0" />
        <geometry>
          <box size="0.06 0.14 0.06" />
        </geometry>
      </collision>

      <visual>
        <origin xyz="0 0 0" rpy="0 0 0"/>
        <geometry>
          <mesh filename="package://open_manipulator_p_description/meshes/link_2.stl" scale="0.001 0.001 0.001"/>
        </geometry>
        <material name="grey"/>
      </visual>

      <inertial>
        <origin xyz="0.00000 0.00080 0.03183" rpy="0 0 0"/>
        <!--<origin xyz="0.00000 -0.06820 -0.00117" rpy="0 0 0"/>-->
        <mass value="0.94658"/>
        <inertia ixx="1.0" ixy="0.0" ixz="0.0" iyy="1.0" iyz="0.0" izz="1.0"/>
        <!--<inertia ixx="0.00152547" ixy="0.0" ixz="0.0" iyy="0.00045954" iyz="-0.00001086" izz="0.00151740" />-->
      </inertial>
    </link>

    <!-- Joint 2 -->
    <joint name="${name}_joint2" type="revolute">
      <parent link="${name}_link2"/>
      <child link="${name}_link3"/>
      <origin xyz="0.0 0.0 0.033" rpy="0 0 0"/>
      <axis xyz="0 1 0"/>
      <limit velocity="6.5" effort="1000" lower="${-pi*0.5}" upper="${pi*0.5}"/>
      <dynamics damping="0.7"/>
    </joint>

    <!-- Transmission 2 -->
    <xacro:SimpleTransmission n="2" joint="${name}_joint2"/>

    <!-- link 3 -->
    <link name="${name}_link3">
      <collision>
        <origin xyz="0.0 0.07 0.01" rpy="0 0 0" />
        <geometry>
          <box size="0.06 0.02 0.09" />
        </geometry>
      </collision>

      <collision>
        <origin xyz="0.0 -0.07 0.01" rpy="0 0 0" />
        <geometry>
          <box size="0.06 0.02 0.09" />
        </geometry>
      </collision>

      <collision>
        <origin xyz="0.0 0.0 0.045" rpy="0 0 0" />
        <geometry>
          <box size="0.06 0.16 0.02" />
        </geometry>
      </collision>

      <collision>
        <origin xyz="0.0 0.0 0.155" rpy="0 0 0" />
        <geometry>
          <box size="0.06 0.09 0.2" />
        </geometry>
      </collision>

      <collision>
        <origin xyz="0.025 0.0 0.26" rpy="0 ${pi/4} 0" />
        <geometry>
          <box size="0.07 0.115 0.08" />
        </geometry>
      </collision>

      <visual>
        <origin xyz="0 0.069 0" rpy="0 0 0"/>
        <geometry>
          <mesh filename="package://open_manipulator_p_description/meshes/link_3.stl" scale="0.001 0.001 0.001"/>
        </geometry>
        <material name="grey"/>
      </visual>

      <inertial>
        <origin xyz="0.01768 0.00019 0.20524" rpy="0 0 0"/>
        <mass value="1.30260"/>
        <inertia ixx="1.0" ixy="0.0" ixz="0.0" iyy="1.0" iyz="0.0" izz="1.0"/>
        <!--<inertia ixx="0.01111021" ixy="0.00001331" ixz="-0.00134208" iyy="0.01046642" iyz="0.00016235" izz="0.00202081" />-->
      </inertial>
    </link>

    <!-- Joint 3 -->
    <joint name="${name}_joint3" type="revolute">
      <parent link="${name}_link3"/>
      <child link="${name}_link4"/>
      <origin xyz="0.03000 0.0 0.26400" rpy="0 0 0"/>
      <axis xyz="0 1 0"/>
      <limit velocity="6.5" effort="1000" lower="${-pi*0.5}" upper="${pi*0.5}"/>
      <dynamics damping="0.7"/>
    </joint>

    <!-- Transmission 3 -->
    <xacro:SimpleTransmission n="3" joint="${name}_joint3"/>

    <!-- link 4 -->
    <link name="${name}_link4">
      <collision>
        <origin xyz="0.01 0.06 0.01" rpy="0 ${pi/4} 0" />
        <geometry>
          <box size="0.06 0.02 0.1" />
        </geometry>
      </collision>

      <collision>
        <origin xyz="0.01 -0.06 0.01" rpy="0 ${pi/4} 0" />
        <geometry>
          <box size="0.06 0.02 0.1" />
        </geometry>
      </collision>

      <collision>
        <origin xyz="0.13 0 0.03" rpy="0 0 0" />
        <geometry>
          <box size="0.2 0.09 0.06" />
        </geometry>
      </collision>

      <collision>
        <origin xyz="0.04 0 0.03" rpy="0 0 0" />
        <geometry>
          <box size="0.03 0.14 0.06" />
        </geometry>
      </collision>

      <visual>
        <origin xyz="0 0.05750 0" rpy="0 0 0"/>
        <geometry>
          <mesh filename="package://open_manipulator_p_description/meshes/link_4.stl" scale="0.001 0.001 0.001"/>
        </geometry>
        <material name="grey"/>
      </visual>

      <inertial>
        <origin xyz="-0.07025 0.00034 -0.00021" rpy="0 0 0"/>
        <mass value="1.15977"/>
        <inertia ixx="1.0" ixy="0.0" ixz="0.0" iyy="1.0" iyz="0.0" izz="1.0"/>
        <!--<inertia ixx="0.00096726" ixy="0.00004383" ixz="-0.00002771" iyy="0.00318801" iyz="0.00000627" izz="0.00341484" />-->
      </inertial>
    </link>

    <!-- Joint 4 -->
    <joint name="${name}_joint4" type="revolute">
      <parent link="${name}_link4"/>
      <child link="${name}_link5"/>
      <origin xyz="0.19500 0.0 0.03000" rpy="0 0 0"/>
      <axis xyz="1 0 0"/>
      <limit velocity="6.5" effort="1000" lower="${-pi*0.5}" upper="${pi*0.5}"/>
      <dynamics damping="0.7"/>
    </joint>

    <!-- Transmission 4 -->
    <xacro:SimpleTransmission n="4" joint="${name}_joint4"/>

    <!-- link 5 -->
    <link name="${name}_link5">
      <collision>
        <origin xyz="0.06 0 0.0" rpy="0 0 0" />
        <geometry>
          <box size="0.055 0.09 0.05" />
        </geometry>
      </collision>

      <visual>
        <origin xyz="0 0 0" rpy="0 0 0"/>
        <geometry>
          <mesh filename="package://open_manipulator_p_description/meshes/link_5.stl" scale="0.001 0.001 0.001"/>
        </geometry>
        <material name="grey"/>
      </visual>

      <inertial>
        <origin xyz="0.05642 -0.00217 0.00002" rpy="0 0 0"/>
        <!--<origin xyz="-0.00658 -0.04717 0.00002" rpy="0 0 0"/>-->
        <mass value="0.44688"/>
        <inertia ixx="1.0" ixy="0.0" ixz="0.0" iyy="1.0" iyz="0.0" izz="1.0"/>
        <!--<inertia ixx="0.00030285" ixy="0.00000761" ixz="0.00000031" iyy="0.00022339" iyz="-0.00000001" izz="0.00039766" />-->
      </inertial>
    </link>

    <!-- Joint 5 -->
    <joint name="${name}_joint5" type="revolute">
      <parent link="${name}_link5"/>
      <child link="${name}_link6"/>
      <origin xyz="0.06300 0.00 0.00000" rpy="0 0 0"/>
      <axis xyz="0 1 0"/>
      <limit velocity="6.5" effort="1000" lower="${-pi*0.5}" upper="${pi*0.5}"/>
      <dynamics damping="0.7"/>
    </joint>

    <!-- Transmission 5 -->
    <xacro:SimpleTransmission n="5" joint="${name}_joint5"/>

    <!-- link 6 -->
    <link name="${name}_link6">
      <collision>
        <origin xyz="0.005 0.045 0.0" rpy="0 0 0" />
        <geometry>
          <box size="0.07 0.015 0.05" />
        </geometry>
      </collision>

      <collision>
        <origin xyz="0.005 -0.045 0.0" rpy="0 0 0" />
        <geometry>
          <box size="0.07 0.015 0.05" />
        </geometry>
      </collision>

      <collision>
        <origin xyz="0.035 0.0 0.0" rpy="0 0 0" />
        <geometry>
          <box size="0.02 0.105 0.05" />
        </geometry>
      </collision>

      <collision>
        <origin xyz="0.08 0.0 0.0" rpy="0 0 0" />
        <geometry>
          <box size="0.09 0.045 0.045" />
        </geometry>
      </collision>

      <visual>
        <origin xyz="0 0.04500 0" rpy="0 0 0"/>
        <geometry>
          <mesh filename="package://open_manipulator_p_description/meshes/link_6.stl" scale="0.001 0.001 0.001"/>
        </geometry>
        <material name="grey"/>
      </visual>

      <inertial>
        <!-- <origin xyz="0.06831 -0.04457 0.00000" rpy="0 0 0"/> -->
        <origin xyz="-0.05469 0.00043 0.00000" rpy="0 0 0"/>
        <mass value="0.43273"/>
        <inertia ixx="1.0" ixy="0.0" ixz="0.0" iyy="1.0" iyz="0.0" izz="1.0"/>
        <!--<inertia ixx="0.00021512" ixy="0.00001009" ixz="0.00000000" iyy="0.00042827" iyz="0.00000000" izz="0.00051436" />-->
      </inertial>
    </link>

    <!-- Joint 6 -->
    <joint name="${name}_joint6" type="revolute">
      <parent link="${name}_link6"/>
      <child link="${name}_end_link"/>
      <origin xyz="0.12300 0.000 0.00000" rpy="0 0 0"/>
      <axis xyz="1 0 0"/>
      <limit velocity="6.5" effort="1000" lower="${-pi*0.5}" upper="${pi*0.5}"/>
      <dynamics damping="0.7"/>
    </joint>

    <!-- Transmission 6 -->
    <xacro:SimpleTransmission n="6" joint="${name}_joint6"/>

    <!-- end link -->
    <link name="${name}_end_link">
      <collision>
        <origin xyz="0.01 0.0 0.0" rpy="0 0 0" />
        <geometry>
          <box size="0.02 0.06 0.045" />
        </geometry>
      </collision>

      <visual>
        <origin xyz="0 0 0" rpy="0 0 0"/>
        <geometry>
          <mesh filename="package://open_manipulator_p_description/meshes/end_link.stl" scale="0.001 0.001 0.001"/>
        </geometry>
        <material name="grey"/>
      </visual>

      <inertial>
        <origin xyz="0.00337 0.00000 0.00000" rpy="0 0 0"/>
        <mass value="0.01919"/>
        <inertia ixx="1.0" ixy="0.0" ixz="0.0" iyy="1.0" iyz="0.0" izz="1.0"/>
        <!--<inertia ixx="0.00000938" ixy="0.0" ixz="0.0" iyy="0.00000338" iyz="0.0" izz="0.00000635" />-->
      </inertial>
    </link>

  </xacro:macro>

</robot>
